The error occurs because the `s3_load_path` attribute is being called as a method with parentheses `()`, but it's actually a string attribute. The error message "TypeError: 'str' object is not callable" indicates that the function is trying to call a string as if it were a function.

To fix the bug, you need to remove the parentheses from `self.s3_load_path()` and just reference the attribute `self.s3_load_path`. This will correctly retrieve the value of the attribute without attempting to call it as a function.

Here's the corrected `run` function:

```python
def run(self):
    
    if not (self.table):
        raise Exception("table needs to be specified")

    path = self.s3_load_path  # Corrected line
    connection = self.output().connect()

    # Rest of the code remains unchanged
    if not self.does_table_exist(connection):
        # try creating table
        logger.info("Creating table %s", self.table)
        connection.reset()
        self.create_table(connection)
    elif self.do_truncate_table():
        logger.info("Truncating table %s", self.table)
        self.truncate_table(connection)

    logger.info("Inserting file: %s", path)
    cursor = connection.cursor()
    self.init_copy(connection)
    self.copy(cursor, path)
    self.output().touch(connection)
    connection.commit()

    # commit and clean up
    connection.close()
```

With this fix, the `run` function should no longer try to call the `s3_load_path` attribute as a method, and the TypeError should be resolved.