To fix the bug in the code snippet, you can replace the line `raise RuntimeError("current IOLoop already exists")` with `return`. This will prevent the `RuntimeError` from being raised and allow the program to continue execution without affecting other successful tests.

Here's the fixed code:

```python
def initialize(self, make_current=None):
    if make_current is None:
        if IOLoop.current(instance=False) is None:
            self.make_current()
    elif make_current:
        if IOLoop.current(instance=False) is None:
            return  # Fix: Return instead of raising RuntimeError
        self.make_current()
```

This fix requires minimal changes to the source code and allows the program to pass the failed test without affecting other tests. Applying this fix to the original project should be straightforward by replacing the buggy line with the fixed line.