The error message indicates that the server is returning a 500 internal server error instead of a 422 validation error when an invalid condecimal is sent to the FastAPI service.

The issue is likely occurring in the `request_validation_exception_handler` function within the `fastapi/exception_handlers.py` file. It seems that the `exc.errors()` method is not providing the correct error information, causing the server to return a 500 error.

To fix the bug, the `request_validation_exception_handler` function needs to be updated to correctly handle the `RequestValidationError` and return a 422 validation error with an explanation of what is invalid about the request.

Here's the corrected code for the `request_validation_exception_handler` function:

```python
from starlette.responses import JSONResponse
from starlette.requests import Request
from starlette.exceptions import RequestValidationError
from starlette.status import HTTP_422_UNPROCESSABLE_ENTITY

async def request_validation_exception_handler(request: Request, exc: RequestValidationError) -> JSONResponse:
    error_messages = exc.errors()
    return JSONResponse(
        status_code=HTTP_422_UNPROCESSABLE_ENTITY, 
        content={"detail": "Validation error", "errors": error_messages}
    )
```

In the corrected code, we use the `exc.errors()` method to retrieve the error messages from the validation exception and include them in the JSON response with a status code of 422. Additionally, we provide a general message "Validation error" along with the specific error messages to indicate what is invalid about the request. This should ensure that the server returns the expected 422 response with an explanation of the validation error.