### Analysis
The buggy function `initialize` is used to set the current `IOLoop` instance. The issue lies in the logic of checking for an existing current `IOLoop` instance. The bug occurs when a second `make_current=True` construction is attempted, causing a `RuntimeError` to be raised incorrectly.

### Potential Error Locations
1. Incorrect logic for checking current `IOLoop` instance.
2. Incorrect handling of the `make_current` parameter.

### Bug Explanation
In the failing test `test_force_current`, an `IOLoop` instance is created with `make_current=True`. The first construction of `IOLoop` checks if a current `IOLoop` instance exists and sets itself as the current instance. However, when attempting to create a second `IOLoop` instance with `make_current=True`, the buggy function erroneously raises a `RuntimeError` even though the `IOLoop` instance is valid.

### Bug Fix Strategy
Update the logic for checking the existence of a current `IOLoop` instance to correctly handle the scenario when a second `make_current=True` construction is attempted. Make sure to only raise a `RuntimeError` when an existing `IOLoop` instance prevents a new instance from being set as the current one.

### Corrected Version
```python
def initialize(self, make_current=None):
    current_instance = IOLoop.current(instance=False)
    
    if make_current is None:
        if current_instance is None:
            self.make_current()
    elif make_current:
        if current_instance is not None:
            raise RuntimeError("current IOLoop already exists")
        self.make_current()
``` 

After applying the above corrections, the function should now correctly handle the scenario of setting a new `IOLoop` instance as the current one without raising a `RuntimeError`. This updated version will pass the failing test `test_force_current`.