### Analysis:
1. The buggy function is `initialize(self, make_current=None)` within the `IOLoop` class.
2. The bug involves checking whether the current `IOLoop` instance exists and then deciding whether to set it as the current instance.
3. The bug seems to be related to handling the `make_current` parameter. The code checks if the current `IOLoop` instance is `None`, but it should actually check if it is not `None`.
4. The bug causes a scenario where even if the current `IOLoop` instance exists, the code incorrectly raises a `RuntimeError`.
   
### Bug Fix Strategy:
To fix the bug, the `initialize` function should check if the current `IOLoop` instance is not `None` when `make_current` is `None`. If `make_current` is `True`, it should raise an error only if the current instance already exists. If `make_current` is `False`, it should not set the current instance.

### Corrected Version:
```python
    def initialize(self, make_current=None):
        if make_current is None:
            if IOLoop.current() is None:
                self.make_current()
        elif make_current:
            if IOLoop.current() is not None:
                raise RuntimeError("current IOLoop already exists")
            self.make_current()
``` 

Applying this correction should fix the bug and make the test function `test_force_current` pass successfully.