To fix the buggy function, we need to update the logic inside the _try_convert_to_date function. The issue seems to be with the conversion to int64 for object dtype and the check for numbers that are out of range. 

Let's update the function as follows:

```python
def _try_convert_to_date(self, data):
    """
    Try to parse a Series like into a date column.

    Try to coerce object in epoch/iso formats and integer/float in epoch
    formats. Return a boolean if parsing was successful.
    """
    # no conversion on empty
    if not len(data):
        return data, False

    new_data = data
    if new_data.dtype == "object":
        try:
            new_data = pd.to_numeric(new_data, errors='ignore')
        except (TypeError, ValueError, OverflowError):
            pass

    if issubclass(new_data.dtype.type, np.number):
        in_range = (
            isna(new_data)
            | (new_data > self.min_stamp)
        )
        if not in_range.all():
            return data, False

    date_units = (self.date_unit,) if self.date_unit else self._STAMP_UNITS
    for date_unit in date_units:
        try:
            new_data = to_datetime(new_data, errors="raise", unit=date_unit, infer_datetime_format=True)
        except (ValueError, OverflowError):
            continue
        return new_data, True
    return data, False
```
In this updated version, we have replaced the astype("int64") with pd.to_numeric to explicitly convert objects to numeric values. We have also modified the check for numbers that are out of range to remove the iNaT condition as it is no longer necessary.

These changes should fix the issues in the previous version and make the function pass the failing test.