Potential error location: 
- The potential error location is within the `verify_collections` function, particularly in the `try` block where the local and remote collections are being processed.

Reasons behind the occurrence of the bug: 
- The bug may be occurring due to issues with handling the local and remote collections, as well as error handling when encountering AnsibleError exceptions.

Possible approaches for fixing the bug:
- Improve error handling for the local and remote collections, including proper exception handling and messaging.
- Ensure that the conditions for verifying the validity of the collection are properly checked and handled.
- Refactor the code to improve readability and maintainability.

Corrected code for the problematic function:

```python
import os
from urllib.parse import urlparse
from ansible.errors import AnsibleError
from ansible.utils.display import Display
from ansible.utils.tempfile import tempdir
from ansible.utils.bytes import to_bytes, to_text
from ansible.module_utils._text import to_text
from ansible.utils.collection_loader import CollectionRequirement
from ansible.errors import AnsibleError

def verify_collections(collections, search_paths, apis, validate_certs, ignore_errors, allow_pre_release=False):
    display = Display()
    with display.progress():
        with tempdir() as b_temp_path:
            for collection in collections:
                try:

                    local_collection = None
                    b_collection = to_bytes(collection[0], errors='surrogate_or_strict')

                    if os.path.isfile(b_collection) or urlparse(collection[0]).scheme.lower() in ['http', 'https'] or len(collection[0].split('.')) != 2:
                        raise AnsibleError(message="'%s' is not a valid collection name. The format namespace.name is expected." % collection[0])

                    collection_name = collection[0]
                    namespace, name = collection_name.split('.')
                    collection_version = collection[1]

                    # Verify local collection exists before downloading it from a galaxy server
                    for search_path in search_paths:
                        b_search_path = to_bytes(os.path.join(search_path, namespace, name), errors='surrogate_or_strict')
                        if os.path.isdir(b_search_path):
                            local_collection = CollectionRequirement.from_path(b_search_path, False)
                            break
                    if local_collection is None:
                        raise AnsibleError(message='Collection %s is not installed in any of the collection paths.' % collection_name)

                    # Download collection on a galaxy server for comparison
                    remote_collection = CollectionRequirement.from_name(collection_name, apis, collection_version, False, parent=None,
                                                                        allow_pre_release=allow_pre_release)

                    download_url = remote_collection.metadata.download_url
                    headers = {}
                    remote_collection.api._add_auth_token(headers, download_url, required=False)
                    b_temp_tar_path = _download_file(download_url, b_temp_path, None, validate_certs, headers=headers)

                    local_collection.verify(remote_collection, search_paths, b_temp_tar_path)

                except AnsibleError as err:
                    if ignore_errors:
                        display.warning("Failed to verify collection %s but skipping due to --ignore-errors being set. "
                                        "Error: %s" % (collection_name, to_text(err)))
                    else:
                        raise
```